Traceback (most recent call last):                                                                               
  File "/lg_rw/fct_test/test_start_dq1.py", line 216, in <module>                                                
    with open(usb_log_file_path, 'a') as usb_log_file:                                                           
FileNotFoundError: [Errno 2] No such file or directory: 'exfat/fct_test_00:50:43:02:fe:01_.log' 
